Workbook

Sheet 1
A1: Factory code | B1: Product Group | C1: Ventmere SKU | D1: model | E1: colour | F1: SET/CTN | G1: G.W/CTN | H1: Carton Size (M) | I1: Volume/CTN | J1: FOB($) (SHENZHEN) | K1: MOQ | L1: 发货订单/预留订单 QTY（SET） | M1: CTN（CTN） | N1: G.W（KGS） | O1: Volume（CBM） | P1: Amount | Q1: SKU
A2: 3P00120-CA00 | B2: Speaker | C2: edifier-p12-brown | D2: P12 | E2: brown | F2: 2 | G2: 11.56 | H2: 0.459*0.344*0.395M | I2: 0.06558408 | J2: 33.9 | K2: 50 | M2: =L2/F2 -> 0 | N2: =M2*G2 -> 0 | O2: =I2*M2 -> 0 | P2: =L2*J2 -> 0 | Q2: edifier-p12-brown
B3: Speaker | D3: D12 | E3: brown | F3: 2 | G3: 12.02 | H3: 0.443*0.337*0.393M | I3: 0.06174605 | J3: 48.4 | K3: 50 | M3: =L3/F3 -> 0 | N3: =M3*G3 -> 0 | O3: =I3*M3 -> 0 | P3: =L3*J3 -> 0 | Q3: edifier-d12
B4: Speaker | D4: MR4 | E4: black | F4: 2 | G4: 12.22 | H4: 0.461*0.345*0.388M | I4: 0.0649138 | J4: 45 | K4: 50 | M4: =L4/F4 -> 0 | N4: =M4*G4 -> 0 | O4: =I4*M4 -> 0 | P4: =L4*J4 -> 0 | Q4: edifier-mr4-black
B5: Speaker | D5: MR4 | E5: white | F5: 2 | G5: 12.22 | H5: 0.461*0.345*0.388M | I5: 0.0649138 | J5: 45 | K5: 50 | M5: =L5/F5 -> 0 | N5: =M5*G5 -> 0 | O5: =I5*M5 -> 0 | P5: =L5*J5 -> 0 | Q5: edifier-mr4-white
A6: 3R1280D-CAA4 | B6: Speaker | C6: edifier-r1280db-wood | D6: R1280DB | E6: brown | F6: 2 | G6: 12.35 | H6: 0.453*0.322*0.395M | I6: 0.06065523 | J6: 54.9 | K6: 50 | M6: =L6/F6 -> 0 | N6: =M6*G6 -> 0 | O6: =I6*M6 -> 0 | P6: =L6*J6 -> 0 | Q6: edifier-r1280db-wood
A7: 3R1280D-CA01 | B7: Speaker | C7: edifier-r1280db-black | D7: R1280DB | E7: black | F7: 2 | G7: 12.35 | H7: 0.453*0.322*0.395M | I7: 0.06065523 | J7: 54.9 | K7: 50 | M7: =L7/F7 -> 0 | N7: =M7*G7 -> 0 | O7: =I7*M7 -> 0 | P7: =L7*J7 -> 0 | Q7: edifier-r1280db-black
A8: 3R1280D-CA01 | B8: Speaker | C8: edifier-r1280db-black | D8: R1280DB | E8: white silver | F8: 2 | G8: 12.35 | H8: 0.453*0.322*0.395M | I8: 0.06065523 | J8: 54.9 | K8: 50 | M8: =L8/F8 -> 0 | N8: =M8*G8 -> 0 | O8: =I8*M8 -> 0 | P8: =L8*J8 -> 0 | Q8: edifier-r1280db-black
A9: 3R1280D-CAA4 | B9: Speaker | D9: R1280DBs | E9: brown | F9: 2 | G9: 12.35 | H9: 0.453*0.322*0.395M | I9: 0.06065523 | J9: 56.9 | K9: 50 | M9: =L9/F9 -> 0 | N9: =M9*G9 -> 0 | O9: =I9*M9 -> 0 | P9: =L9*J9 -> 0 | Q9: edifier-r1280dbs-wood
A10: 3R1280D-CA01 | B10: Speaker | D10: R1280DBs | E10: black | F10: 2 | G10: 12.35 | H10: 0.453*0.322*0.395M | I10: 0.06065523 | J10: 56.9 | K10: 50 | M10: =L10/F10 -> 0 | N10: =M10*G10 -> 0 | O10: =I10*M10 -> 0 | P10: =L10*J10 -> 0 | Q10: edifier-r1280dbs-black
A11: 3R1700B-CA06 | B11: Speaker | C11: edifier-r1700bt | D11: R1700BT | E11: brown | F11: 2 | G11: 16.95 | H11: 0.462*0.352*0.412M | I11: 0.07035542 | J11: 62.3 | K11: 50 | M11: =L11/F11 -> 0 | N11: =M11*G11 -> 0 | O11: =I11*M11 -> 0 | P11: =L11*J11 -> 0 | Q11: edifier-r1700bt-brown
A12: 3R1700B-CA06 | B12: Speaker | C12: edifier-r1700bt | D12: R1700BT | E12: black | F12: 2 | G12: 16.95 | H12: 0.462*0.352*0.412M | I12: 0.07035542 | J12: 62.3 | K12: 50 | M12: =L12/F12 -> 0 | N12: =M12*G12 -> 0 | O12: =I12*M12 -> 0 | P12: =L12*J12 -> 0 | Q12: edifier-r1700bt-black
B13: Speaker | C13: edifier-r1700bt | D13: R1700BT | E13: white silver | F13: 2 | G13: 16.95 | H13: 0.462*0.352*0.412M | I13: 0.07035542 | J13: 62.3 | K13: 50 | M13: =L13/F13 -> 0 | N13: =M13*G13 -> 0 | O13: =I13*M13 -> 0 | P13: =L13*J13 -> 0 | Q13: edifier-r1700bt-white silver
A14: 3R1700B-CA06 | B14: Speaker | D14: R1700BTs | E14: brown | F14: 2 | G14: 16.95 | H14: 0.464*0.352*0.412M | I14: 0.07065673 | J14: 67 | K14: 50 | M14: =L14/F14 -> 0 | N14: =M14*G14 -> 0 | O14: =I14*M14 -> 0 | P14: =L14*J14 -> 0 | Q14: edifier-r1700bts-brown
B15: Speaker | C15: edifier-r1280t | D15: R1280T | E15: brown | F15: 2 | G15: 12.31 | H15: 0.453*0.322*0.395M | I15: 0.06065523 | J15: 41.8 | K15: 100 | M15: =L15/F15 -> 0 | N15: =M15*G15 -> 0 | O15: =I15*M15 -> 0 | P15: =L15*J15 -> 0 | Q15: edifier-r1280t
B16: Speaker | D16: R1280Ts | E16: brown | F16: 2 | G16: 12.31 | H16: 0.453*0.322*0.395M | I16: 0.06065523 | J16: 46.35 | K16: 100 | M16: =L16/F16 -> 0 | N16: =M16*G16 -> 0 | O16: =I16*M16 -> 0 | P16: =L16*J16 -> 0 | Q16: edifier-r1280ts-brown
A17: 3R1850D-CA00 | B17: Speaker | C17: edifier-r1850db-black | D17: R1850DB | E17: black | F17: 2 | G17: 17.21 | H17: 0.462*0.352*0.412M | I17: 0.07035542 | J17: 82.9 | K17: 40 | M17: =L17/F17 -> 0 | N17: =M17*G17 -> 0 | O17: =I17*M17 -> 0 | P17: =L17*J17 -> 0 | Q17: edifier-r1850db-black
A18: . | B18: Speaker | C18: edifier-r2000db-black | D18: R2000DB | E18: black | F18: 1 | G18: 12.34 | H18: 0.477*0.322*0.393M | I18: 0.06351844 | J18: 115.1 | K18: 20 | M18: =L18/F18 -> 0 | N18: =M18*G18 -> 0 | O18: =I18*M18 -> 0 | P18: =L18*J18 -> 0 | Q18: edifier-r2000db-black
A19: 3R2000D-CA09 | B19: Speaker | C19: edifier-r2000db-wood | D19: R2000DB | E19: brown | F19: 1 | G19: 12.34 | H19: 0.477*0.322*0.393M | I19: 0.06351844 | J19: 93.6 | K19: 20 | M19: =L19/F19 -> 0 | N19: =M19*G19 -> 0 | O19: =I19*M19 -> 0 | P19: =L19*J19 -> 0 | Q19: edifier-r2000db-wood
B20: Speaker | D20: R2850DB | E20: black | F20: 1 | G20: 26.7 | H20: 0.679*0.434*0.581M | I20: 0.17746312 | J20: 148.4 | K20: 20 | M20: =L20/F20 -> 0 | N20: =M20*G20 -> 0 | O20: =I20*M20 -> 0 | P20: =L20*J20 -> 0 | Q20: edifier-r2850db-black
B21: Speaker | D21: R33BT | E21: black | F21: 4 | G21: 15.9 | H21: 0.615*0.425*0.375M | I21: 0.102641 | J21: 31.3 | K21: 48 | M21: =L21/F21 -> 0 | N21: =M21*G21 -> 0 | O21: =I21*M21 -> 0 | P21: =L21*J21 -> 0 | Q21: edifier-r33bt-black
A22: 3R0980T-CA00 | B22: Speaker | C22: edifier-r980t | D22: R980T | E22: black | F22: 2 | G22: 10.03 | H22: 0.459*0.329*0.395M | I22: 0.06276528 | J22: 27 | K22: 48 | M22: =L22/F22 -> 0 | N22: =M22*G22 -> 0 | O22: =I22*M22 -> 0 | P22: =L22*J22 -> 0 | Q22: edifier-r980t
B23: Speaker | D23: S1000MKII | E23: brown | F23: 1 | G23: 19 | H23: 0.520*0.365*0.433M | I23: 0.08605275 | J23: 139.8 | K23: 20 | M23: =L23/F23 -> 0 | N23: =M23*G23 -> 0 | O23: =I23*M23 -> 0 | P23: =L23*J23 -> 0 | Q23: ed-s1000mkii-brown
B24: Speaker | D24: S2000MKⅢ | E24: brown | F24: 1 | G24: 20.54 | H24: 0.549*0.378*0.448M | I24: 0.09717936 | J24: 193.5 | K24: 20 | M24: =L24/F24 -> 0 | N24: =M24*G24 -> 0 | O24: =I24*M24 -> 0 | P24: =L24*J24 -> 0 | Q24: ed-s2000mkiii-brown
B25: Speaker | D25: S3000MKⅡ | E25: brown | F25: 1 | G25: 24.6 | H25: 0.602*0.388*0.477M | I25: 0.11617434 | J25: 322.6 | K25: 10 | M25: =L25/F25 -> 0 | N25: =M25*G25 -> 0 | O25: =I25*M25 -> 0 | P25: =L25*J25 -> 0 | Q25: ed-s3000mkii-brown
B26: Speaker | D26: S350DB | E26: brown | F26: 1 | G26: 19.73 | H26: 0.629*0.376*0.382M | I26: 0.09468917 | J26: 149.5 | K26: 20 | M26: =L26/F26 -> 0 | N26: =M26*G26 -> 0 | O26: =I26*M26 -> 0 | P26: =L26*J26 -> 0 | Q26: edifier-s350db
B27: Speaker | D27: S351DB | E27: black | F27: 1 | G27: 21.9 | H27: 0.629*0.376*0.382M | I27: 0.09468917 | J27: 149.5 | K27: 20 | M27: =L27/F27 -> 0 | N27: =M27*G27 -> 0 | O27: =I27*M27 -> 0 | P27: =L27*J27 -> 0 | Q27: edifier-s351db
B28: Speaker | C28: edifier-s360db-brown | D28: S360DB | E28: brown | F28: 1 | G28: 22.54 | H28: 0.670*0.428*0.415M | I28: 0.12421688 | J28: 193.5 | K28: 20 | M28: =L28/F28 -> 0 | N28: =M28*G28 -> 0 | O28: =I28*M28 -> 0 | P28: =L28*J28 -> 0 | Q28: edifier-s360db-brown
B29: Speaker | D29: S1000W | E29: brown | F29: 1 | G29: 20.61 | H29: 0.549*0.378*0.448M | I29: 0.09717936 | J29: 165 | K29: 10 | M29: =L29/F29 -> 0 | N29: =M29*G29 -> 0 | O29: =I29*M29 -> 0 | P29: =L29*J29 -> 0 | Q29: edifier-s1000w-brown
B30: Speaker | D30: QD35 | E30: black | F30: 4 | G30: 3.52 | H30: 0.396*0.356*0.560M | I30: 0.08251377 | J30: 75 | K30: 20 | M30: =L30/F30 -> 0 | N30: =M30*G30 -> 0 | O30: =I30*M30 -> 0 | P30: =L30*J30 -> 0 | Q30: edifier-qd35-black
B31: Speaker | D31: QD35 | E31: white | F31: 4 | G31: 3.52 | H31: 0.396*0.356*0.560M | I31: 0.08251377 | J31: 75 | K31: 20 | M31: =L31/F31 -> 0 | N31: =M31*G31 -> 0 | O31: =I31*M31 -> 0 | P31: =L31*J31 -> 0 | Q31: edifier-qd35-white
B32: Speaker | D32: QD25 | E32: black | F32: 8 | G32: 11.79 | H32: 0.477*0.306*0.358M | I32: 0.05516394 | J32: 46.5 | K32: 48 | M32: =L32/F32 -> 0 | N32: =M32*G32 -> 0 | O32: =I32*M32 -> 0 | P32: =L32*J32 -> 0 | Q32: edifier-qd25-black
B33: Speaker | D33: QD25 | E33: white | F33: 8 | G33: 11.79 | H33: 0.477*0.306*0.358M | I33: 0.05516394 | J33: 46.5 | K33: 48 | M33: =L33/F33 -> 0 | N33: =M33*G33 -> 0 | O33: =I33*M33 -> 0 | P33: =L33*J33 -> 0 | Q33: edifier-qd25-white
B34: Speaker | D34: QS20 | E34: black | F34: 16 | G34: 8.79 | H34: 0.379*0.270*0.292M | I34: 0.0318912 | J34: 24.5 | K34: 96 | M34: =L34/F34 -> 0 | N34: =M34*G34 -> 0 | O34: =I34*M34 -> 0 | P34: =L34*J34 -> 0 | Q34: edifier-qs20-black
B35: Speaker | D35: QS20 | E35: red | F35: 16 | G35: 8.79 | H35: 0.379*0.270*0.292M | I35: 0.0318912 | J35: 24.5 | K35: 96 | M35: =L35/F35 -> 0 | N35: =M35*G35 -> 0 | O35: =I35*M35 -> 0 | P35: =L35*J35 -> 0 | Q35: edifier-qs20-red
B36: Speaker | D36: QS20 | E36: silver | F36: 16 | G36: 8.79 | H36: 0.379*0.270*0.292M | I36: 0.0318912 | J36: 24.5 | K36: 96 | M36: =L36/F36 -> 0 | N36: =M36*G36 -> 0 | O36: =I36*M36 -> 0 | P36: =L36*J36 -> 0 | Q36: edifier-qs20-silver
B37: Speaker | D37: QR65 | E37: black | F37: 2 | G37: 16.01 | H37: 0.575*0.382*0.363M | I37: 0.08372358 | J37: 155 | K37: 20 | M37: =L37/F37 -> 0 | N37: =M37*G37 -> 0 | O37: =I37*M37 -> 0 | P37: =L37*J37 -> 0 | Q37: edifier-qr65-black
B38: Speaker | D38: QR65 | E38: white | F38: 2 | G38: 16.01 | H38: 0.575*0.382*0.363M | I38: 0.08372358 | J38: 155 | K38: 20 | M38: =L38/F38 -> 0 | N38: =M38*G38 -> 0 | O38: =I38*M38 -> 0 | P38: =L38*J38 -> 0 | Q38: edifier-qr65-white
B39: Speaker | D39: MP230 | E39: brown | F39: 16 | G39: 18.12 | H39: 0.544*0.445*0.249M | I39: 0.06398595 | J39: 38 | K39: 80 | M39: =L39/F39 -> 0 | N39: =M39*G39 -> 0 | O39: =I39*M39 -> 0 | P39: =L39*J39 -> 0 | Q39: edifier-mp230-brown
B40: Speaker | D40: MP230 | E40: green black | F40: 16 | G40: 18.12 | H40: 0.544*0.445*0.249M | I40: 0.06398595 | J40: 38 | K40: 80 | M40: =L40/F40 -> 0 | N40: =M40*G40 -> 0 | O40: =I40*M40 -> 0 | P40: =L40*J40 -> 0 | Q40: edifier-mp230-black
...

Sheet 卡板计算
A1: Factory code | B1: Product Group | C1: model | D1: colour | E1: SET/CTN | F1: G.W/CTN | G1: SIZE/CTN | H1: Volume/CTN | I1: FOB($) (SHENZHEN) | J1: 可发货库存 2022/03/30 | K1: 发货订单 QTY（SET） | L1: CTN（CTN） | M1: G.W（KGS） | N1: Volume（CBM） | O1: Amount | P1: 卡板箱数/层 | Q1: 层/卡板 | R1: 总箱数/卡板 | S1: 订单卡板数 | T1: Note
B2: ='1'!B2 -> Speaker | C2: ='1'!D2 -> P12 | D2: ='1'!E2 -> brown | E2: ='1'!F2 -> 2 | F2: ='1'!G2 -> 11.56 | G2: ='1'!H2 -> 0.459*0.344*0.395M | H2: ='1'!I2 -> 0.06558408 | I2: ='1'!J2 -> 33.9 | K2: ='1'!L2 -> 0 | L2: =K2/E2 -> 0 | M2: =L2*F2 -> 0 | N2: =H2*L2 -> 0 | O2: =K2*I2 -> 0 | P2: 8 | Q2: 6 | R2: =Q2*P2 -> 48 | S2: 0
A3: 3R0980T-CA00 | B3: ='1'!B3 -> Speaker | C3: ='1'!D3 -> D12 | D3: ='1'!E3 -> brown | E3: ='1'!F3 -> 2 | F3: ='1'!G3 -> 12.02 | G3: ='1'!H3 -> 0.443*0.337*0.393M | H3: ='1'!I3 -> 0.06174605 | I3: ='1'!J3 -> 48.4 | K3: ='1'!L3 -> 0 | L3: =K3/E3 -> 0 | M3: =L3*F3 -> 0 | N3: =H3*L3 -> 0 | O3: =K3*I3 -> 0 | P3: 8 | Q3: 6 | R3: =Q3*P3 -> 48 | S3: =L3/R3 -> 0 | T3: 新包装
A4: 3P00120-CA00 | B4: ='1'!B4 -> Speaker | C4: ='1'!D4 -> MR4 | D4: ='1'!E4 -> black | E4: ='1'!F4 -> 2 | F4: ='1'!G4 -> 12.22 | G4: ='1'!H4 -> 0.461*0.345*0.388M | H4: ='1'!I4 -> 0.0649138 | I4: ='1'!J4 -> 45 | K4: ='1'!L4 -> 0 | L4: =K4/E4 -> 0 | M4: =L4*F4 -> 0 | N4: =H4*L4 -> 0 | O4: =K4*I4 -> 0 | P4: 8 | Q4: 4 | R4: =Q4*P4 -> 32 | S4: =L4/R4 -> 0
B5: ='1'!B5 -> Speaker | C5: ='1'!D5 -> MR4 | D5: ='1'!E5 -> white | E5: ='1'!F5 -> 2 | F5: ='1'!G5 -> 12.22 | G5: ='1'!H5 -> 0.461*0.345*0.388M | H5: ='1'!I5 -> 0.0649138 | I5: ='1'!J5 -> 45 | K5: ='1'!L5 -> 0 | L5: =K5/E5 -> 0 | M5: =L5*F5 -> 0 | N5: =H5*L5 -> 0 | O5: =K5*I5 -> 0 | P5: 8 | Q5: 4 | R5: =Q5*P5 -> 32 | S5: =L5/R5 -> 0
B6: ='1'!#REF! -> #REF! | C6: ='1'!#REF! -> #REF! | D6: ='1'!#REF! -> #REF! | E6: ='1'!#REF! -> #REF! | F6: ='1'!#REF! -> #REF! | G6: ='1'!#REF! -> #REF! | H6: ='1'!#REF! -> #REF! | I6: ='1'!#REF! -> #REF! | K6: ='1'!#REF! -> #REF! | L6: =K6/E6 -> #REF! | M6: =L6*F6 -> #REF! | N6: =H6*L6 -> #REF! | O6: =K6*I6 -> #REF! | P6: 24 | Q6: 13 | R6: =Q6*P6 -> 312 | S6: =L6/R6 -> #REF!
B7: ='1'!B6 -> Speaker | C7: ='1'!D6 -> R1280DB | D7: ='1'!E6 -> brown | E7: ='1'!F6 -> 2 | F7: ='1'!G6 -> 12.35 | G7: ='1'!H6 -> 0.453*0.322*0.395M | H7: ='1'!I6 -> 0.06065523 | I7: ='1'!J6 -> 54.9 | K7: ='1'!L6 -> 0 | L7: =K7/E7 -> 0 | M7: =L7*F7 -> 0 | N7: =H7*L7 -> 0 | O7: =K7*I7 -> 0 | P7: 8 | Q7: 6 | R7: =Q7*P7 -> 48 | S7: =L7/R7 -> 0
B8: ='1'!B7 -> Speaker | C8: ='1'!D7 -> R1280DB | D8: ='1'!E7 -> black | E8: ='1'!F7 -> 2 | F8: ='1'!G7 -> 12.35 | G8: ='1'!H7 -> 0.453*0.322*0.395M | H8: ='1'!I7 -> 0.06065523 | I8: ='1'!J7 -> 54.9 | K8: ='1'!L7 -> 0 | L8: =K8/E8 -> 0 | M8: =L8*F8 -> 0 | N8: =H8*L8 -> 0 | O8: =K8*I8 -> 0 | P8: 8 | Q8: 6 | R8: =Q8*P8 -> 48 | S8: =L8/R8 -> 0
B9: ='1'!B9 -> Speaker | C9: ='1'!D9 -> R1280DBs | D9: ='1'!E9 -> brown | E9: ='1'!F9 -> 2 | F9: ='1'!G9 -> 12.35 | G9: ='1'!H9 -> 0.453*0.322*0.395M | H9: ='1'!I9 -> 0.06065523 | I9: ='1'!J9 -> 56.9 | K9: ='1'!L9 -> 0 | L9: =K9/E9 -> 0 | M9: =L9*F9 -> 0 | N9: =H9*L9 -> 0 | O9: =K9*I9 -> 0 | P9: 8 | Q9: 6 | R9: =Q9*P9 -> 48 | S9: =L9/R9 -> 0
B10: ='1'!B10 -> Speaker | C10: ='1'!D10 -> R1280DBs | D10: ='1'!E10 -> black | E10: ='1'!F10 -> 2 | F10: ='1'!G10 -> 12.35 | G10: ='1'!H10 -> 0.453*0.322*0.395M | H10: ='1'!I10 -> 0.06065523 | I10: ='1'!J10 -> 56.9 | K10: ='1'!L10 -> 0 | L10: =K10/E10 -> 0 | M10: =L10*F10 -> 0 | N10: =H10*L10 -> 0 | O10: =K10*I10 -> 0 | P10: 8 | Q10: 6 | R10: =Q10*P10 -> 48 | S10: =L10/R10 -> 0
B11: ='1'!B14 -> Speaker | C11: ='1'!D14 -> R1700BTs | D11: ='1'!E14 -> brown | E11: ='1'!F14 -> 2 | F11: ='1'!G14 -> 16.95 | G11: ='1'!H14 -> 0.464*0.352*0.412M | H11: ='1'!I14 -> 0.07065673 | I11: ='1'!J14 -> 67 | K11: ='1'!L14 -> 0 | L11: =K11/E11 -> 0 | M11: =L11*F11 -> 0 | N11: =H11*L11 -> 0 | O11: =K11*I11 -> 0 | P11: 7 | Q11: 5 | R11: =Q11*P11 -> 35 | S11: =L11/R11 -> 0
B12: ='1'!B16 -> Speaker | C12: ='1'!D16 -> R1280Ts | D12: ='1'!E16 -> brown | E12: ='1'!F16 -> 2 | F12: ='1'!G16 -> 12.31 | G12: ='1'!H16 -> 0.453*0.322*0.395M | H12: ='1'!I16 -> 0.06065523 | I12: ='1'!J16 -> 46.35 | K12: ='1'!L16 -> 0 | L12: =K12/E12 -> 0 | M12: =L12*F12 -> 0 | N12: =H12*L12 -> 0 | O12: =K12*I12 -> 0 | P12: 8 | Q12: 6 | R12: =Q12*P12 -> 48 | S12: =L12/R12 -> 0
B13: ='1'!B11 -> Speaker | C13: ='1'!D11 -> R1700BT | D13: ='1'!E11 -> brown | E13: ='1'!F11 -> 2 | F13: ='1'!G11 -> 16.95 | G13: ='1'!H11 -> 0.462*0.352*0.412M | H13: ='1'!I11 -> 0.07035542 | I13: ='1'!J11 -> 62.3 | K13: ='1'!L11 -> 0 | L13: =K13/E13 -> 0 | M13: =L13*F13 -> 0 | N13: =H13*L13 -> 0 | O13: =K13*I13 -> 0 | P13: 7 | Q13: 5 | R13: =Q13*P13 -> 35 | S13: =L13/R13 -> 0
B14: ='1'!B17 -> Speaker | C14: ='1'!D17 -> R1850DB | D14: ='1'!E17 -> black | E14: ='1'!F17 -> 2 | F14: ='1'!G17 -> 17.21 | G14: ='1'!H17 -> 0.462*0.352*0.412M | H14: ='1'!I17 -> 0.07035542 | I14: ='1'!J17 -> 82.9 | K14: ='1'!L17 -> 0 | L14: =K14/E14 -> 0 | M14: =L14*F14 -> 0 | N14: =H14*L14 -> 0 | O14: =K14*I14 -> 0 | P14: 7 | Q14: 5 | R14: =Q14*P14 -> 35 | S14: =L14/R14 -> 0
B15: ='1'!B18 -> Speaker | C15: ='1'!D18 -> R2000DB | D15: ='1'!E18 -> black | E15: ='1'!F18 -> 1 | F15: ='1'!G18 -> 12.34 | G15: ='1'!H18 -> 0.477*0.322*0.393M | H15: ='1'!I18 -> 0.06351844 | I15: ='1'!J18 -> 115.1 | K15: ='1'!L18 -> 0 | L15: =K15/E15 -> 0 | M15: =L15*F15 -> 0 | N15: =H15*L15 -> 0 | O15: =K15*I15 -> 0 | P15: 4 | Q15: 6 | R15: =Q15*P15 -> 24
B16: ='1'!B19 -> Speaker | C16: ='1'!D19 -> R2000DB | D16: ='1'!E19 -> brown | E16: ='1'!F19 -> 1 | F16: ='1'!G19 -> 12.34 | G16: ='1'!H19 -> 0.477*0.322*0.393M | H16: ='1'!I19 -> 0.06351844 | I16: ='1'!J19 -> 93.6 | K16: ='1'!L19 -> 0 | L16: =K16/E16 -> 0 | M16: =L16*F16 -> 0 | N16: =H16*L16 -> 0 | O16: =K16*I16 -> 0 | P16: 4 | Q16: 6 | R16: =Q16*P16 -> 24
B17: ='1'!B20 -> Speaker | C17: ='1'!D20 -> R2850DB | D17: ='1'!E20 -> black | E17: ='1'!F20 -> 1 | F17: ='1'!G20 -> 26.7 | G17: ='1'!H20 -> 0.679*0.434*0.581M | H17: ='1'!I20 -> 0.17746312 | I17: ='1'!J20 -> 148.4 | K17: ='1'!L20 -> 0 | L17: =K17/E17 -> 0 | M17: =L17*F17 -> 0 | N17: =H17*L17 -> 0 | O17: =K17*I17 -> 0 | R17: =Q17*P17 -> 0
B18: ='1'!B21 -> Speaker | C18: ='1'!D21 -> R33BT | D18: ='1'!E21 -> black | E18: ='1'!F21 -> 4 | F18: ='1'!G21 -> 15.9 | G18: ='1'!H21 -> 0.615*0.425*0.375M | H18: ='1'!I21 -> 0.102641 | I18: ='1'!J21 -> 31.3 | K18: ='1'!L21 -> 0 | L18: =K18/E18 -> 0 | M18: =L18*F18 -> 0 | N18: =H18*L18 -> 0 | O18: =K18*I18 -> 0 | R18: =Q18*P18 -> 0
B19: ='1'!B22 -> Speaker | C19: ='1'!D22 -> R980T | D19: ='1'!E22 -> black | E19: ='1'!F22 -> 2 | F19: ='1'!G22 -> 10.03 | G19: ='1'!H22 -> 0.459*0.329*0.395M | H19: ='1'!I22 -> 0.06276528 | I19: ='1'!J22 -> 27 | K19: ='1'!L22 -> 0 | L19: =K19/E19 -> 0 | M19: =L19*F19 -> 0 | N19: =H19*L19 -> 0 | O19: =K19*I19 -> 0 | P19: 4 | Q19: 6 | R19: =Q19*P19 -> 24
B20: ='1'!B23 -> Speaker | C20: ='1'!D23 -> S1000MKII | D20: ='1'!E23 -> brown | E20: ='1'!F23 -> 1 | F20: ='1'!G23 -> 19 | G20: ='1'!H23 -> 0.520*0.365*0.433M | H20: ='1'!I23 -> 0.08605275 | I20: ='1'!J23 -> 139.8 | K20: ='1'!L23 -> 0 | L20: =K20/E20 -> 0 | M20: =L20*F20 -> 0 | N20: =H20*L20 -> 0 | O20: =K20*I20 -> 0 | P20: 6 | Q20: 5 | R20: =Q20*P20 -> 30
B21: ='1'!B24 -> Speaker | C21: ='1'!D24 -> S2000MKⅢ | D21: ='1'!E24 -> brown | E21: ='1'!F24 -> 1 | F21: ='1'!G24 -> 20.54 | G21: ='1'!H24 -> 0.549*0.378*0.448M | H21: ='1'!I24 -> 0.09717936 | I21: ='1'!J24 -> 193.5 | K21: ='1'!L24 -> 0 | L21: =K21/E21 -> 0 | M21: =L21*F21 -> 0 | N21: =H21*L21 -> 0 | O21: =K21*I21 -> 0 | P21: 6 | Q21: 5 | R21: =Q21*P21 -> 30
B22: ='1'!B26 -> Speaker | C22: ='1'!D26 -> S350DB | D22: ='1'!E26 -> brown | E22: ='1'!F26 -> 1 | F22: ='1'!G26 -> 19.73 | G22: ='1'!H26 -> 0.629*0.376*0.382M | H22: ='1'!I26 -> 0.09468917 | I22: ='1'!J26 -> 149.5 | K22: ='1'!L26 -> 0 | L22: =K22/E22 -> 0 | M22: =L22*F22 -> 0 | N22: =H22*L22 -> 0 | O22: =K22*I22 -> 0 | P22: 5 | Q22: 6 | R22: =Q22*P22 -> 30
B23: ='1'!B27 -> Speaker | C23: ='1'!D27 -> S351DB | D23: ='1'!E27 -> black | E23: ='1'!F27 -> 1 | F23: ='1'!G27 -> 21.9 | G23: ='1'!H27 -> 0.629*0.376*0.382M | H23: ='1'!I27 -> 0.09468917 | I23: ='1'!J27 -> 149.5 | K23: ='1'!L27 -> 0 | L23: =K23/E23 -> 0 | M23: =L23*F23 -> 0 | N23: =H23*L23 -> 0 | O23: =K23*I23 -> 0 | P23: 5 | Q23: 6 | R23: =Q23*P23 -> 30
B24: ='1'!B28 -> Speaker | C24: ='1'!D28 -> S360DB | D24: ='1'!E28 -> brown | E24: ='1'!F28 -> 1 | F24: ='1'!G28 -> 22.54 | G24: ='1'!H28 -> 0.670*0.428*0.415M | H24: ='1'!I28 -> 0.12421688 | I24: ='1'!J28 -> 193.5 | K24: ='1'!L28 -> 0 | L24: =K24/E24 -> 0 | M24: =L24*F24 -> 0 | N24: =H24*L24 -> 0 | O24: =K24*I24 -> 0 | P24: 2 | Q24: 5 | R24: =Q24*P24 -> 10
B25: ='1'!B29 -> Speaker | C25: ='1'!D29 -> S1000W | D25: ='1'!E29 -> brown | E25: ='1'!F29 -> 1 | F25: ='1'!G29 -> 20.61 | G25: ='1'!H29 -> 0.549*0.378*0.448M | H25: ='1'!I29 -> 0.09717936 | I25: ='1'!J29 -> 165 | J25: 165 | K25: ='1'!L29 -> 0
B26: ='1'!B51 -> Stand | C26: ='1'!D51 -> SS02 | D26: ='1'!E51 -> black | E26: ='1'!F51 -> 1 | F26: ='1'!G51 -> 17.5 | G26: ='1'!H51 -> 0.725*0.485*0.287M | H26: ='1'!I51 -> 0.1062369 | I26: ='1'!J51 -> 65 | K26: ='1'!L51 -> 0 | L26: =K26/E26 -> 0 | M26: =L26*F26 -> 0 | N26: =H26*L26 -> 0 | O26: =K26*I26 -> 0
B27: ='1'!B52 -> Stand | C27: ='1'!D52 -> SS02C | D27: ='1'!E52 -> black | E27: ='1'!F52 -> 1 | F27: ='1'!G52 -> 17.5 | G27: ='1'!H52 -> 0.725*0.485*0.287M | H27: ='1'!I52 -> 0.1062369 | I27: ='1'!J52 -> 65 | K27: ='1'!L52 -> 0
B28: ='1'!B53 -> Stand | C28: ='1'!D53 -> SS03 | D28: ='1'!E53 -> brown | E28: ='1'!F53 -> 1 | F28: ='1'!G53 -> 18.4 | G28: ='1'!H53 -> 0.694*0.487*0.305M | H28: ='1'!I53 -> 0.10833102 | I28: ='1'!J53 -> 65 | K28: ='1'!L53 -> 0 | L28: =K28/E28 -> 0 | M28: =L28*F28 -> 0 | N28: =H28*L28 -> 0 | O28: =K28*I28 -> 0
B29: ='1'!#REF! -> #REF! | C29: ='1'!#REF! -> #REF! | D29: ='1'!#REF! -> #REF! | E29: ='1'!#REF! -> #REF! | F29: ='1'!#REF! -> #REF! | G29: ='1'!#REF! -> #REF! | H29: ='1'!#REF! -> #REF! | I29: ='1'!#REF! -> #REF! | K29: ='1'!#REF! -> #REF!
B30: ='1'!#REF! -> #REF! | C30: ='1'!#REF! -> #REF! | D30: ='1'!#REF! -> #REF! | E30: ='1'!#REF! -> #REF! | F30: ='1'!#REF! -> #REF! | G30: ='1'!#REF! -> #REF! | H30: ='1'!#REF! -> #REF! | I30: ='1'!#REF! -> #REF! | K30: ='1'!#REF! -> #REF!
B31: ='1'!#REF! -> #REF! | C31: ='1'!#REF! -> #REF! | D31: ='1'!#REF! -> #REF! | E31: ='1'!#REF! -> #REF! | F31: ='1'!#REF! -> #REF! | G31: ='1'!#REF! -> #REF! | H31: ='1'!#REF! -> #REF! | I31: ='1'!#REF! -> #REF! | K31: ='1'!#REF! -> #REF! | L31: =K31/E31 -> #REF! | M31: =L31*F31 -> #REF! | N31: =H31*L31 -> #REF! | O31: =K31*I31 -> #REF!
B32: ='1'!#REF! -> #REF! | C32: ='1'!#REF! -> #REF! | D32: ='1'!#REF! -> #REF! | E32: ='1'!#REF! -> #REF! | F32: ='1'!#REF! -> #REF! | G32: ='1'!#REF! -> #REF! | H32: ='1'!#REF! -> #REF! | I32: ='1'!#REF! -> #REF! | K32: ='1'!#REF! -> #REF! | L32: =K32/E32 -> #REF! | M32: =L32*F32 -> #REF! | N32: =H32*L32 -> #REF! | O32: =K32*I32 -> #REF!
B33: ='1'!#REF! -> #REF! | C33: ='1'!#REF! -> #REF! | D33: ='1'!#REF! -> #REF! | E33: ='1'!#REF! -> #REF! | F33: ='1'!#REF! -> #REF! | G33: ='1'!#REF! -> #REF! | H33: ='1'!#REF! -> #REF! | I33: ='1'!#REF! -> #REF! | K33: ='1'!#REF! -> #REF! | L33: =K33/E33 -> #REF! | M33: =L33*F33 -> #REF! | N33: =H33*L33 -> #REF! | O33: =K33*I33 -> #REF!
B34: ='1'!B57 -> Headphone | C34: ='1'!D57 -> P205 | D34: ='1'!E57 -> black | E34: ='1'!F57 -> 40 | F34: ='1'!G57 -> 2.05 | G34: ='1'!H57 -> 0.367*0.26*0.156M | H34: ='1'!I57 -> 0.01636428 | I34: ='1'!J57 -> 3.4 | K34: ='1'!L57 -> 0 | L34: =K34/E34 -> 0 | M34: =L34*F34 -> 0 | N34: =H34*L34 -> 0 | O34: =K34*I34 -> 0
B35: ='1'!B58 -> Headphone | C35: ='1'!D58 -> P205 | D35: ='1'!E58 -> white | E35: ='1'!F58 -> 40 | F35: ='1'!G58 -> 2.05 | G35: ='1'!H58 -> 0.367*0.26*0.156M | H35: ='1'!I58 -> 0.01636428 | I35: ='1'!J58 -> 3.4 | K35: ='1'!L58 -> 0 | L35: =K35/E35 -> 0 | M35: =L35*F35 -> 0 | N35: =H35*L35 -> 0 | O35: =K35*I35 -> 0
B36: ='1'!#REF! -> #REF! | C36: ='1'!#REF! -> #REF! | D36: ='1'!#REF! -> #REF! | E36: ='1'!#REF! -> #REF! | F36: ='1'!#REF! -> #REF! | G36: ='1'!#REF! -> #REF! | H36: ='1'!#REF! -> #REF! | I36: ='1'!#REF! -> #REF! | K36: ='1'!#REF! -> #REF!
B37: ='1'!#REF! -> #REF! | C37: ='1'!#REF! -> #REF! | D37: ='1'!#REF! -> #REF! | E37: ='1'!#REF! -> #REF! | F37: ='1'!#REF! -> #REF! | G37: ='1'!#REF! -> #REF! | H37: ='1'!#REF! -> #REF! | I37: ='1'!#REF! -> #REF! | K37: ='1'!#REF! -> #REF!
B38: ='1'!#REF! -> #REF! | C38: ='1'!#REF! -> #REF! | D38: ='1'!#REF! -> #REF! | E38: ='1'!#REF! -> #REF! | F38: ='1'!#REF! -> #REF! | G38: ='1'!#REF! -> #REF! | H38: ='1'!#REF! -> #REF! | I38: ='1'!#REF! -> #REF! | K38: ='1'!#REF! -> #REF!
B39: ='1'!#REF! -> #REF! | C39: ='1'!#REF! -> #REF! | D39: ='1'!#REF! -> #REF! | E39: ='1'!#REF! -> #REF! | F39: ='1'!#REF! -> #REF! | G39: ='1'!#REF! -> #REF! | H39: ='1'!#REF! -> #REF! | I39: ='1'!#REF! -> #REF! | K39: ='1'!#REF! -> #REF!
B40: ='1'!#REF! -> #REF! | C40: ='1'!#REF! -> #REF! | D40: ='1'!#REF! -> #REF! | E40: ='1'!#REF! -> #REF! | F40: ='1'!#REF! -> #REF! | G40: ='1'!#REF! -> #REF! | H40: ='1'!#REF! -> #REF! | I40: ='1'!#REF! -> #REF! | K40: ='1'!#REF! -> #REF!
...

Sheet Sheet1
A2: 出口型号名 | B2: VM/VC(USD) 工厂提货价
A3: X2 | B3: 13
A4: X3 | B4: /
A5: X3s | B5: 16
A6: X3 To-U | B6: /
A7: To-U2
A8: To-U6+
A9: To-U2 mini
A10: To-U3 Pro
A11: TWS1 Pro | B11: 26
A12: TWS200 Plus | B12: 28
A13: TWS NB2 Pro | B13: 40
A14: Neobuds Pro | B14: 48
A15: Neobuds Pro
A16: Neobuds S
A17: TWS330 NB | B17: 30
A18: W200Tmini | B18: 17.5
A19: W240TN | B19: 30.5
A20: W220T | B20: 27
A21: W280NB
A22: WH500
A23: W600BT | B23: 15
A24: W800BT PLUS | B24: v
A25: W820NB | B25: 28
A26: W820NB PLUS | B26: 28
A27: WH950NB
A28: S3 | B28: 127
A29: P205 | B29: 3.7
A30: K5000 | B30: 17
A31: K6500 | B31: 35
A32: H180 | B32: 2.3
A33: P180 | B33: 3.8
A34: H185 | B34: 3.2
A35: H190 | B35: 5
A36: P190 | B36: 6.5
A37: H840 | B37: 10.2
A38: P841 | B38: 12.5
A39: H650 | B39: 8.8
A40: H850 | B40: 15.8
A41: H880 | B41: /
...
